WARNING 2020-02-08 15:44:23,026 base 152 Not Found: /
WARNING 2020-02-08 15:44:23,026 basehttp 124 "GET / HTTP/1.1" 404 2011
WARNING 2020-02-08 15:44:23,238 base 152 Not Found: /favicon.ico
WARNING 2020-02-08 15:44:23,238 basehttp 124 "GET /favicon.ico HTTP/1.1" 404 2062
WARNING 2020-02-08 15:44:47,403 base 152 Not Found: /image_codes/11/
WARNING 2020-02-08 15:44:47,403 basehttp 124 "GET /image_codes/11/ HTTP/1.1" 404 2080
WARNING 2020-02-08 15:44:47,695 base 152 Not Found: /favicon.ico
WARNING 2020-02-08 15:44:47,696 basehttp 124 "GET /favicon.ico HTTP/1.1" 404 2068
WARNING 2020-02-08 15:45:09,863 base 152 Not Found: /
WARNING 2020-02-08 15:45:09,864 basehttp 124 "GET / HTTP/1.1" 404 2011
WARNING 2020-02-08 15:45:17,013 base 152 Not Found: /image_codes/11/
WARNING 2020-02-08 15:45:17,014 basehttp 124 "GET /image_codes/11/ HTTP/1.1" 404 2074
ERROR 2020-02-08 15:45:36,957 exceptions 25 [<mall.apps.verifications.views.ImageCodeView object at 0x10ff52e90>] Error 61 connecting to 127.0.0.1:6379. Connection refused.
ERROR 2020-02-08 15:45:37,015 basehttp 124 "GET /image_codes/11/ HTTP/1.1" 507 9665
INFO 2020-02-08 15:45:37,095 basehttp 124 "GET /static/rest_framework/css/bootstrap-tweaks.css HTTP/1.1" 304 0
INFO 2020-02-08 15:45:37,099 basehttp 124 "GET /static/rest_framework/css/default.css HTTP/1.1" 304 0
INFO 2020-02-08 15:45:37,100 basehttp 124 "GET /static/rest_framework/css/prettify.css HTTP/1.1" 304 0
INFO 2020-02-08 15:45:37,101 basehttp 124 "GET /static/rest_framework/js/ajax-form.js HTTP/1.1" 304 0
INFO 2020-02-08 15:45:37,105 basehttp 124 "GET /static/rest_framework/js/csrf.js HTTP/1.1" 304 0
INFO 2020-02-08 15:45:37,107 basehttp 124 "GET /static/rest_framework/js/bootstrap.min.js HTTP/1.1" 200 39680
INFO 2020-02-08 15:45:37,111 basehttp 124 "GET /static/rest_framework/js/prettify-min.js HTTP/1.1" 304 0
INFO 2020-02-08 15:45:37,112 basehttp 124 "GET /static/rest_framework/js/jquery-3.4.1.min.js HTTP/1.1" 200 88145
INFO 2020-02-08 15:45:37,115 basehttp 124 "GET /static/rest_framework/js/default.js HTTP/1.1" 304 0
INFO 2020-02-08 15:45:37,115 basehttp 124 "GET /static/rest_framework/css/bootstrap.min.css HTTP/1.1" 200 121457
INFO 2020-02-08 15:45:37,149 basehttp 124 "GET /static/rest_framework/img/grid.png HTTP/1.1" 304 0
INFO 2020-02-08 15:45:45,925 basehttp 124 "GET /image_codes/11/ HTTP/1.1" 200 3360
INFO 2020-02-08 15:58:07,523 basehttp 124 "GET /image_codes/976f600d-56fa-4118-928a-7ba5a7e2502c/ HTTP/1.1" 200 3377
INFO 2020-02-08 15:58:08,774 basehttp 124 "GET /image_codes/a925cc97-5d0c-4e2a-a63d-0f3d92319968/ HTTP/1.1" 200 3482
INFO 2020-02-08 15:58:09,227 basehttp 124 "GET /image_codes/ba094ed4-638e-4779-996c-4d01f97f6a76/ HTTP/1.1" 200 3127
INFO 2020-02-08 15:58:09,420 basehttp 124 "GET /image_codes/1a6c51a3-f766-460e-a2ff-ea70443cca06/ HTTP/1.1" 200 3111
INFO 2020-02-08 15:58:09,621 basehttp 124 "GET /image_codes/b1ecbfdd-ec00-4122-8fc8-5209a80821dc/ HTTP/1.1" 200 3237
INFO 2020-02-08 16:13:26,163 basehttp 124 "GET /image_codes/afbb8cad-d09a-4863-9ead-e2aae3d433c1/ HTTP/1.1" 200 2926
INFO 2020-02-08 16:14:07,607 basehttp 124 "GET /image_codes/a055dc81-4c5a-4e5a-b925-e6a2cdcebb77/ HTTP/1.1" 200 3266
WARNING 2020-02-08 18:31:45,476 base 152 Not Found: /
WARNING 2020-02-08 18:31:45,477 basehttp 124 "GET / HTTP/1.1" 404 2291
INFO 2020-02-08 18:31:54,313 basehttp 124 "GET /sms_codes/17719715757 HTTP/1.1" 301 0
ERROR 2020-02-08 18:31:54,323 exception 135 Internal Server Error: /sms_codes/17719715757/
Traceback (most recent call last):
  File "/usr/local/lib/python3.7/site-packages/django/core/handlers/exception.py", line 41, in inner
    response = get_response(request)
  File "/usr/local/lib/python3.7/site-packages/django/core/handlers/base.py", line 187, in _get_response
    response = self.process_exception_by_middleware(e, request)
  File "/usr/local/lib/python3.7/site-packages/django/core/handlers/base.py", line 185, in _get_response
    response = wrapped_callback(request, *callback_args, **callback_kwargs)
  File "/usr/local/lib/python3.7/site-packages/django/views/decorators/csrf.py", line 58, in wrapped_view
    return view_func(*args, **kwargs)
  File "/usr/local/lib/python3.7/site-packages/django/views/generic/base.py", line 68, in view
    return self.dispatch(request, *args, **kwargs)
  File "/usr/local/lib/python3.7/site-packages/rest_framework/views.py", line 505, in dispatch
    response = self.handle_exception(exc)
  File "/usr/local/lib/python3.7/site-packages/rest_framework/views.py", line 465, in handle_exception
    self.raise_uncaught_exception(exc)
  File "/usr/local/lib/python3.7/site-packages/rest_framework/views.py", line 476, in raise_uncaught_exception
    raise exc
  File "/usr/local/lib/python3.7/site-packages/rest_framework/views.py", line 502, in dispatch
    response = handler(request, *args, **kwargs)
  File "/Users/jill/PycharmProjects/django_mall/mall/mall/apps/verifications/views.py", line 35, in get
    s.is_valid(raise_excrption=True)
TypeError: is_valid() got an unexpected keyword argument 'raise_excrption'
ERROR 2020-02-08 18:31:54,424 basehttp 124 "GET /sms_codes/17719715757/ HTTP/1.1" 500 93791
WARNING 2020-02-08 18:32:44,625 base 152 Not Found: /
WARNING 2020-02-08 18:32:44,626 basehttp 124 "GET / HTTP/1.1" 404 2291
WARNING 2020-02-08 18:32:54,292 basehttp 124 "GET /sms_codes/17719715757/ HTTP/1.1" 400 9785
WARNING 2020-02-08 18:36:14,165 base 152 Not Found: /
WARNING 2020-02-08 18:36:14,165 basehttp 124 "GET / HTTP/1.1" 404 2297
WARNING 2020-02-08 18:36:14,489 base 152 Not Found: /favicon.ico
WARNING 2020-02-08 18:36:14,490 basehttp 124 "GET /favicon.ico HTTP/1.1" 404 2348
WARNING 2020-02-08 18:36:21,290 base 152 Not Found: /register.html
WARNING 2020-02-08 18:36:21,290 basehttp 124 "GET /register.html HTTP/1.1" 404 2354
INFO 2020-02-08 18:36:50,690 basehttp 124 "GET /image_codes/71c579aa-3444-4839-9f95-01979778203d/ HTTP/1.1" 200 3381
INFO 2020-02-08 18:36:53,902 basehttp 124 "GET /image_codes/7675e18d-b9ae-4cad-a1a1-dac59d0ff90e/ HTTP/1.1" 200 3077
INFO 2020-02-08 18:36:54,356 basehttp 124 "GET /image_codes/263633e4-fd58-41d7-92b8-a75e1f22056f/ HTTP/1.1" 200 2965
WARNING 2020-02-08 18:36:57,128 base 152 Not Found: /register.html
WARNING 2020-02-08 18:36:57,129 basehttp 124 "GET /register.html HTTP/1.1" 404 2354
WARNING 2020-02-08 18:36:58,422 base 152 Not Found: /register.html
WARNING 2020-02-08 18:36:58,422 basehttp 124 "GET /register.html HTTP/1.1" 404 2354
INFO 2020-02-08 18:37:11,253 basehttp 124 "GET /image_codes/f7c9a3d9-aaa5-4219-8de6-b85bcf2a8d42/ HTTP/1.1" 200 3402
WARNING 2020-02-08 18:37:23,773 base 152 Not Found: /mobiles/17719715757/count/
WARNING 2020-02-08 18:37:23,774 basehttp 124 "GET /mobiles/17719715757/count/ HTTP/1.1" 404 2393
WARNING 2020-02-08 18:37:42,388 base 152 Not Found: /mobiles/17719715757/count/
WARNING 2020-02-08 18:37:42,390 basehttp 124 "GET /mobiles/17719715757/count/ HTTP/1.1" 404 2393
WARNING 2020-02-08 18:37:42,392 basehttp 124 "GET /sms_codes/17719715757/?text=ssss&image_code_id=f7c9a3d9-aaa5-4219-8de6-b85bcf2a8d42 HTTP/1.1" 400 46
INFO 2020-02-08 18:52:05,804 basehttp 124 "GET /image_codes/92c48a86-e8fa-469c-a738-22411946fa60/ HTTP/1.1" 200 3247
WARNING 2020-02-08 18:52:08,419 base 152 Not Found: /mobiles/17719715757/count/
WARNING 2020-02-08 18:52:08,420 basehttp 124 "GET /mobiles/17719715757/count/ HTTP/1.1" 404 2393
WARNING 2020-02-08 18:52:11,110 base 152 Not Found: /mobiles/17719715757/count/
WARNING 2020-02-08 18:52:11,113 basehttp 124 "GET /mobiles/17719715757/count/ HTTP/1.1" 404 2393
WARNING 2020-02-08 18:52:11,121 basehttp 124 "GET /sms_codes/17719715757/?text=ssss&image_code_id=92c48a86-e8fa-469c-a738-22411946fa60 HTTP/1.1" 400 46
INFO 2020-02-08 19:15:14,961 basehttp 124 "GET /image_codes/0d7aaca3-1b74-45bc-aeb1-a80b77095907/ HTTP/1.1" 200 2907
INFO 2020-02-08 19:15:20,550 basehttp 124 "GET /image_codes/2b077eb9-21c2-4e01-ae2e-c7874759bbf4/ HTTP/1.1" 200 2931
INFO 2020-02-08 19:15:21,374 basehttp 124 "GET /image_codes/de27b498-b3cc-4e80-93d5-29625e8fd169/ HTTP/1.1" 200 3154
WARNING 2020-02-08 19:15:24,759 base 152 Not Found: /mobiles/17719715757/count/
WARNING 2020-02-08 19:15:24,760 basehttp 124 "GET /mobiles/17719715757/count/ HTTP/1.1" 404 2393
WARNING 2020-02-08 19:21:07,102 base 152 Not Found: /
WARNING 2020-02-08 19:21:07,103 basehttp 124 "GET / HTTP/1.1" 404 2291
WARNING 2020-02-08 19:21:16,557 base 152 Not Found: /register.html
WARNING 2020-02-08 19:21:16,558 basehttp 124 "GET /register.html HTTP/1.1" 404 2348
INFO 2020-02-08 19:21:29,147 basehttp 124 "GET /image_codes/c6ee2c2b-2345-45be-a6b7-ea1d4aff03f0/ HTTP/1.1" 200 3639
WARNING 2020-02-08 19:21:41,049 base 152 Not Found: /mobiles/17719715757/count/
WARNING 2020-02-08 19:21:41,050 basehttp 124 "GET /mobiles/17719715757/count/ HTTP/1.1" 404 2393
WARNING 2020-02-08 19:21:42,368 base 152 Not Found: /mobiles/17719715757/count/
WARNING 2020-02-08 19:21:42,371 basehttp 124 "GET /mobiles/17719715757/count/ HTTP/1.1" 404 2393
WARNING 2020-02-08 19:21:42,374 basehttp 124 "GET /sms_codes/17719715757/?text=1111&image_code_id=c6ee2c2b-2345-45be-a6b7-ea1d4aff03f0 HTTP/1.1" 400 46
INFO 2020-02-08 19:21:42,406 basehttp 124 "GET /image_codes/f58ffd24-b31f-47ca-9b51-4df49a7a616a/ HTTP/1.1" 200 3129
WARNING 2020-02-08 19:22:02,122 base 152 Not Found: /mobiles/17719715757/count/
WARNING 2020-02-08 19:22:02,125 basehttp 124 "GET /mobiles/17719715757/count/ HTTP/1.1" 404 2393
INFO 2020-02-08 19:22:02,364 views 52 发送短信验证码正常[mobile:17719715757]
INFO 2020-02-08 19:22:02,365 basehttp 124 "GET /sms_codes/17719715757/?text=vlnc&image_code_id=f58ffd24-b31f-47ca-9b51-4df49a7a616a HTTP/1.1" 200 16
INFO 2020-02-09 15:37:46,334 basehttp 124 "GET /image_codes/f7ea5106-00b0-4216-8855-6ccee69f9635/ HTTP/1.1" 200 3456
WARNING 2020-02-09 15:37:48,476 base 152 Not Found: /mobiles/17719715757/count/
WARNING 2020-02-09 15:37:48,477 basehttp 124 "GET /mobiles/17719715757/count/ HTTP/1.1" 404 2393
WARNING 2020-02-09 15:37:50,992 base 152 Not Found: /mobiles/17719715757/count/
WARNING 2020-02-09 15:37:50,995 basehttp 124 "GET /mobiles/17719715757/count/ HTTP/1.1" 404 2393
INFO 2020-02-09 15:37:51,066 basehttp 124 "GET /sms_codes/17719715757/?text=rwfk&image_code_id=f7ea5106-00b0-4216-8855-6ccee69f9635 HTTP/1.1" 200 16
INFO 2020-02-09 15:37:51,290 tasks 17 发送短信验证码正常[mobile:17719715757]
WARNING 2020-02-09 17:16:16,578 base 152 Not Found: /
WARNING 2020-02-09 17:16:16,579 basehttp 124 "GET / HTTP/1.1" 404 2833
WARNING 2020-02-09 17:16:16,743 base 152 Not Found: /favicon.ico
WARNING 2020-02-09 17:16:16,743 basehttp 124 "GET /favicon.ico HTTP/1.1" 404 2884
INFO 2020-02-09 17:16:31,403 basehttp 124 "GET /image_codes/71b1af60-bfab-47a3-aa23-4ad8e5004370/ HTTP/1.1" 200 2998
ERROR 2020-02-09 17:16:33,655 exception 135 Internal Server Error: /usernames/jillhero/count/
Traceback (most recent call last):
  File "/usr/local/lib/python3.7/site-packages/django/core/handlers/exception.py", line 41, in inner
    response = get_response(request)
  File "/usr/local/lib/python3.7/site-packages/django/core/handlers/base.py", line 187, in _get_response
    response = self.process_exception_by_middleware(e, request)
  File "/usr/local/lib/python3.7/site-packages/django/core/handlers/base.py", line 185, in _get_response
    response = wrapped_callback(request, *callback_args, **callback_kwargs)
  File "/usr/local/lib/python3.7/site-packages/django/views/decorators/csrf.py", line 58, in wrapped_view
    return view_func(*args, **kwargs)
  File "/usr/local/lib/python3.7/site-packages/django/views/generic/base.py", line 68, in view
    return self.dispatch(request, *args, **kwargs)
  File "/usr/local/lib/python3.7/site-packages/rest_framework/views.py", line 505, in dispatch
    response = self.handle_exception(exc)
  File "/usr/local/lib/python3.7/site-packages/rest_framework/views.py", line 465, in handle_exception
    self.raise_uncaught_exception(exc)
  File "/usr/local/lib/python3.7/site-packages/rest_framework/views.py", line 476, in raise_uncaught_exception
    raise exc
  File "/usr/local/lib/python3.7/site-packages/rest_framework/views.py", line 502, in dispatch
    response = handler(request, *args, **kwargs)
  File "/Users/jill/PycharmProjects/django_mall/mall/mall/apps/users/views.py", line 18, in get
    count = User.objects.filter(username=username).count()
NameError: name 'User' is not defined
ERROR 2020-02-09 17:16:33,721 basehttp 124 "GET /usernames/jillhero/count/ HTTP/1.1" 500 16720
ERROR 2020-02-09 17:16:43,363 exception 135 Internal Server Error: /mobiles/17719715757/count/
Traceback (most recent call last):
  File "/usr/local/lib/python3.7/site-packages/django/core/handlers/exception.py", line 41, in inner
    response = get_response(request)
  File "/usr/local/lib/python3.7/site-packages/django/core/handlers/base.py", line 187, in _get_response
    response = self.process_exception_by_middleware(e, request)
  File "/usr/local/lib/python3.7/site-packages/django/core/handlers/base.py", line 185, in _get_response
    response = wrapped_callback(request, *callback_args, **callback_kwargs)
  File "/usr/local/lib/python3.7/site-packages/django/views/decorators/csrf.py", line 58, in wrapped_view
    return view_func(*args, **kwargs)
  File "/usr/local/lib/python3.7/site-packages/django/views/generic/base.py", line 68, in view
    return self.dispatch(request, *args, **kwargs)
  File "/usr/local/lib/python3.7/site-packages/rest_framework/views.py", line 505, in dispatch
    response = self.handle_exception(exc)
  File "/usr/local/lib/python3.7/site-packages/rest_framework/views.py", line 465, in handle_exception
    self.raise_uncaught_exception(exc)
  File "/usr/local/lib/python3.7/site-packages/rest_framework/views.py", line 476, in raise_uncaught_exception
    raise exc
  File "/usr/local/lib/python3.7/site-packages/rest_framework/views.py", line 502, in dispatch
    response = handler(request, *args, **kwargs)
  File "/Users/jill/PycharmProjects/django_mall/mall/mall/apps/users/views.py", line 28, in get
    count = User.objects.filter(mobile=mobile).count()
NameError: name 'User' is not defined
ERROR 2020-02-09 17:16:43,378 basehttp 124 "GET /mobiles/17719715757/count/ HTTP/1.1" 500 16720
ERROR 2020-02-09 17:16:46,997 exception 135 Internal Server Error: /mobiles/17719715757/count/
Traceback (most recent call last):
  File "/usr/local/lib/python3.7/site-packages/django/core/handlers/exception.py", line 41, in inner
    response = get_response(request)
  File "/usr/local/lib/python3.7/site-packages/django/core/handlers/base.py", line 187, in _get_response
    response = self.process_exception_by_middleware(e, request)
  File "/usr/local/lib/python3.7/site-packages/django/core/handlers/base.py", line 185, in _get_response
    response = wrapped_callback(request, *callback_args, **callback_kwargs)
  File "/usr/local/lib/python3.7/site-packages/django/views/decorators/csrf.py", line 58, in wrapped_view
    return view_func(*args, **kwargs)
  File "/usr/local/lib/python3.7/site-packages/django/views/generic/base.py", line 68, in view
    return self.dispatch(request, *args, **kwargs)
  File "/usr/local/lib/python3.7/site-packages/rest_framework/views.py", line 505, in dispatch
    response = self.handle_exception(exc)
  File "/usr/local/lib/python3.7/site-packages/rest_framework/views.py", line 465, in handle_exception
    self.raise_uncaught_exception(exc)
  File "/usr/local/lib/python3.7/site-packages/rest_framework/views.py", line 476, in raise_uncaught_exception
    raise exc
  File "/usr/local/lib/python3.7/site-packages/rest_framework/views.py", line 502, in dispatch
    response = handler(request, *args, **kwargs)
  File "/Users/jill/PycharmProjects/django_mall/mall/mall/apps/users/views.py", line 28, in get
    count = User.objects.filter(mobile=mobile).count()
NameError: name 'User' is not defined
ERROR 2020-02-09 17:16:47,023 basehttp 124 "GET /mobiles/17719715757/count/ HTTP/1.1" 500 16720
INFO 2020-02-09 17:16:47,086 basehttp 124 "GET /sms_codes/17719715757/?text=7gcx&image_code_id=71b1af60-bfab-47a3-aa23-4ad8e5004370 HTTP/1.1" 200 16
INFO 2020-02-09 17:16:47,352 tasks 17 发送短信验证码正常[mobile:17719715757]
ERROR 2020-02-09 17:16:58,173 exception 135 Internal Server Error: /usernames/jillhero/count/
Traceback (most recent call last):
  File "/usr/local/lib/python3.7/site-packages/django/core/handlers/exception.py", line 41, in inner
    response = get_response(request)
  File "/usr/local/lib/python3.7/site-packages/django/core/handlers/base.py", line 187, in _get_response
    response = self.process_exception_by_middleware(e, request)
  File "/usr/local/lib/python3.7/site-packages/django/core/handlers/base.py", line 185, in _get_response
    response = wrapped_callback(request, *callback_args, **callback_kwargs)
  File "/usr/local/lib/python3.7/site-packages/django/views/decorators/csrf.py", line 58, in wrapped_view
    return view_func(*args, **kwargs)
  File "/usr/local/lib/python3.7/site-packages/django/views/generic/base.py", line 68, in view
    return self.dispatch(request, *args, **kwargs)
  File "/usr/local/lib/python3.7/site-packages/rest_framework/views.py", line 505, in dispatch
    response = self.handle_exception(exc)
  File "/usr/local/lib/python3.7/site-packages/rest_framework/views.py", line 465, in handle_exception
    self.raise_uncaught_exception(exc)
  File "/usr/local/lib/python3.7/site-packages/rest_framework/views.py", line 476, in raise_uncaught_exception
    raise exc
  File "/usr/local/lib/python3.7/site-packages/rest_framework/views.py", line 502, in dispatch
    response = handler(request, *args, **kwargs)
  File "/Users/jill/PycharmProjects/django_mall/mall/mall/apps/users/views.py", line 18, in get
    count = User.objects.filter(username=username).count()
NameError: name 'User' is not defined
ERROR 2020-02-09 17:16:58,174 exception 135 Internal Server Error: /mobiles/17719715757/count/
Traceback (most recent call last):
  File "/usr/local/lib/python3.7/site-packages/django/core/handlers/exception.py", line 41, in inner
    response = get_response(request)
  File "/usr/local/lib/python3.7/site-packages/django/core/handlers/base.py", line 187, in _get_response
    response = self.process_exception_by_middleware(e, request)
  File "/usr/local/lib/python3.7/site-packages/django/core/handlers/base.py", line 185, in _get_response
    response = wrapped_callback(request, *callback_args, **callback_kwargs)
  File "/usr/local/lib/python3.7/site-packages/django/views/decorators/csrf.py", line 58, in wrapped_view
    return view_func(*args, **kwargs)
  File "/usr/local/lib/python3.7/site-packages/django/views/generic/base.py", line 68, in view
    return self.dispatch(request, *args, **kwargs)
  File "/usr/local/lib/python3.7/site-packages/rest_framework/views.py", line 505, in dispatch
    response = self.handle_exception(exc)
  File "/usr/local/lib/python3.7/site-packages/rest_framework/views.py", line 465, in handle_exception
    self.raise_uncaught_exception(exc)
  File "/usr/local/lib/python3.7/site-packages/rest_framework/views.py", line 476, in raise_uncaught_exception
    raise exc
  File "/usr/local/lib/python3.7/site-packages/rest_framework/views.py", line 502, in dispatch
    response = handler(request, *args, **kwargs)
  File "/Users/jill/PycharmProjects/django_mall/mall/mall/apps/users/views.py", line 28, in get
    count = User.objects.filter(mobile=mobile).count()
NameError: name 'User' is not defined
INFO 2020-02-09 17:16:58,176 basehttp 124 "OPTIONS /users/ HTTP/1.1" 200 0
ERROR 2020-02-09 17:16:58,210 basehttp 124 "GET /usernames/jillhero/count/ HTTP/1.1" 500 16720
ERROR 2020-02-09 17:16:58,223 basehttp 124 "GET /mobiles/17719715757/count/ HTTP/1.1" 500 16721
WARNING 2020-02-09 17:16:58,230 basehttp 124 "POST /users/ HTTP/1.1" 400 35
ERROR 2020-02-09 17:17:09,575 exception 135 Internal Server Error: /usernames/jillhero/count/
Traceback (most recent call last):
  File "/usr/local/lib/python3.7/site-packages/django/core/handlers/exception.py", line 41, in inner
    response = get_response(request)
  File "/usr/local/lib/python3.7/site-packages/django/core/handlers/base.py", line 187, in _get_response
    response = self.process_exception_by_middleware(e, request)
  File "/usr/local/lib/python3.7/site-packages/django/core/handlers/base.py", line 185, in _get_response
    response = wrapped_callback(request, *callback_args, **callback_kwargs)
  File "/usr/local/lib/python3.7/site-packages/django/views/decorators/csrf.py", line 58, in wrapped_view
    return view_func(*args, **kwargs)
  File "/usr/local/lib/python3.7/site-packages/django/views/generic/base.py", line 68, in view
    return self.dispatch(request, *args, **kwargs)
  File "/usr/local/lib/python3.7/site-packages/rest_framework/views.py", line 505, in dispatch
    response = self.handle_exception(exc)
  File "/usr/local/lib/python3.7/site-packages/rest_framework/views.py", line 465, in handle_exception
    self.raise_uncaught_exception(exc)
  File "/usr/local/lib/python3.7/site-packages/rest_framework/views.py", line 476, in raise_uncaught_exception
    raise exc
  File "/usr/local/lib/python3.7/site-packages/rest_framework/views.py", line 502, in dispatch
    response = handler(request, *args, **kwargs)
  File "/Users/jill/PycharmProjects/django_mall/mall/mall/apps/users/views.py", line 18, in get
    count = User.objects.filter(username=username).count()
NameError: name 'User' is not defined
ERROR 2020-02-09 17:17:09,577 exception 135 Internal Server Error: /mobiles/17719715757/count/
Traceback (most recent call last):
  File "/usr/local/lib/python3.7/site-packages/django/core/handlers/exception.py", line 41, in inner
    response = get_response(request)
  File "/usr/local/lib/python3.7/site-packages/django/core/handlers/base.py", line 187, in _get_response
    response = self.process_exception_by_middleware(e, request)
  File "/usr/local/lib/python3.7/site-packages/django/core/handlers/base.py", line 185, in _get_response
    response = wrapped_callback(request, *callback_args, **callback_kwargs)
  File "/usr/local/lib/python3.7/site-packages/django/views/decorators/csrf.py", line 58, in wrapped_view
    return view_func(*args, **kwargs)
  File "/usr/local/lib/python3.7/site-packages/django/views/generic/base.py", line 68, in view
    return self.dispatch(request, *args, **kwargs)
  File "/usr/local/lib/python3.7/site-packages/rest_framework/views.py", line 505, in dispatch
    response = self.handle_exception(exc)
  File "/usr/local/lib/python3.7/site-packages/rest_framework/views.py", line 465, in handle_exception
    self.raise_uncaught_exception(exc)
  File "/usr/local/lib/python3.7/site-packages/rest_framework/views.py", line 476, in raise_uncaught_exception
    raise exc
  File "/usr/local/lib/python3.7/site-packages/rest_framework/views.py", line 502, in dispatch
    response = handler(request, *args, **kwargs)
  File "/Users/jill/PycharmProjects/django_mall/mall/mall/apps/users/views.py", line 28, in get
    count = User.objects.filter(mobile=mobile).count()
NameError: name 'User' is not defined
WARNING 2020-02-09 17:17:09,610 basehttp 124 "POST /users/ HTTP/1.1" 400 35
ERROR 2020-02-09 17:17:09,611 basehttp 124 "GET /usernames/jillhero/count/ HTTP/1.1" 500 16720
ERROR 2020-02-09 17:17:09,626 basehttp 124 "GET /mobiles/17719715757/count/ HTTP/1.1" 500 16721
INFO 2020-02-09 17:18:21,738 basehttp 124 "GET /image_codes/1c108b8a-e824-4633-a0d6-4d9f1d41b61c/ HTTP/1.1" 200 2926
INFO 2020-02-09 17:18:26,842 basehttp 124 "GET /usernames/jillhero/count/ HTTP/1.1" 200 33
INFO 2020-02-09 17:18:32,382 basehttp 124 "GET /mobiles/17719715757/count/ HTTP/1.1" 200 34
INFO 2020-02-09 17:18:36,225 basehttp 124 "GET /mobiles/17719715757/count/ HTTP/1.1" 200 34
INFO 2020-02-09 17:18:36,290 basehttp 124 "GET /sms_codes/17719715757/?text=xf5z&image_code_id=1c108b8a-e824-4633-a0d6-4d9f1d41b61c HTTP/1.1" 200 16
INFO 2020-02-09 17:18:36,539 tasks 17 发送短信验证码正常[mobile:17719715757]
INFO 2020-02-09 17:18:47,600 basehttp 124 "GET /mobiles/17719715757/count/ HTTP/1.1" 200 34
INFO 2020-02-09 17:18:47,603 basehttp 124 "GET /usernames/jillhero/count/ HTTP/1.1" 200 33
WARNING 2020-02-09 17:18:47,605 basehttp 124 "POST /users/ HTTP/1.1" 400 35
INFO 2020-02-09 17:20:09,724 basehttp 124 "GET /usernames/jillhero/count/ HTTP/1.1" 200 33
INFO 2020-02-09 17:20:22,692 basehttp 124 "GET /image_codes/e9513869-10df-47a9-9c5c-5e6616a2f772/ HTTP/1.1" 200 3133
INFO 2020-02-09 17:20:26,488 basehttp 124 "GET /usernames/jillhero/count/ HTTP/1.1" 200 33
INFO 2020-02-09 17:20:31,829 basehttp 124 "GET /mobiles/17719715757/count/ HTTP/1.1" 200 34
INFO 2020-02-09 17:20:35,857 basehttp 124 "GET /mobiles/17719715757/count/ HTTP/1.1" 200 34
INFO 2020-02-09 17:20:35,976 basehttp 124 "GET /sms_codes/17719715757/?text=tmal&image_code_id=e9513869-10df-47a9-9c5c-5e6616a2f772 HTTP/1.1" 200 16
INFO 2020-02-09 17:20:36,168 tasks 17 发送短信验证码正常[mobile:17719715757]
INFO 2020-02-09 17:20:51,842 basehttp 124 "GET /mobiles/17719715757/count/ HTTP/1.1" 200 34
INFO 2020-02-09 17:20:51,846 basehttp 124 "GET /usernames/jillhero/count/ HTTP/1.1" 200 33
WARNING 2020-02-09 17:20:51,853 basehttp 124 "POST /users/ HTTP/1.1" 400 35
INFO 2020-02-09 17:25:32,713 basehttp 124 "GET /usernames/jillhero/count/ HTTP/1.1" 200 33
INFO 2020-02-09 17:25:40,555 basehttp 124 "GET /mobiles/17719715757/count/ HTTP/1.1" 200 34
INFO 2020-02-09 17:25:40,934 basehttp 124 "GET /image_codes/3e3b6c3e-67a4-4a44-874b-9a8384e8eea0/ HTTP/1.1" 200 3443
INFO 2020-02-09 17:25:43,774 basehttp 124 "GET /usernames/jillhero/count/ HTTP/1.1" 200 33
INFO 2020-02-09 17:25:49,006 basehttp 124 "GET /mobiles/17719715757/count/ HTTP/1.1" 200 34
INFO 2020-02-09 17:25:53,364 basehttp 124 "GET /mobiles/17719715757/count/ HTTP/1.1" 200 34
INFO 2020-02-09 17:25:53,481 basehttp 124 "GET /sms_codes/17719715757/?text=5kry&image_code_id=3e3b6c3e-67a4-4a44-874b-9a8384e8eea0 HTTP/1.1" 200 16
INFO 2020-02-09 17:25:53,720 tasks 17 发送短信验证码正常[mobile:17719715757]
INFO 2020-02-09 17:26:04,174 basehttp 124 "GET /mobiles/17719715757/count/ HTTP/1.1" 200 34
INFO 2020-02-09 17:26:04,179 basehttp 124 "GET /usernames/jillhero/count/ HTTP/1.1" 200 33
WARNING 2020-02-09 17:26:04,189 basehttp 124 "POST /users/ HTTP/1.1" 400 35
INFO 2020-02-09 17:27:06,640 basehttp 124 "GET /image_codes/30cf328d-2a48-424a-89b0-d8263ecd0790/ HTTP/1.1" 200 3575
INFO 2020-02-09 17:27:08,925 basehttp 124 "GET /usernames/jillhero/count/ HTTP/1.1" 200 33
INFO 2020-02-09 17:27:14,188 basehttp 124 "GET /mobiles/17719715757/count/ HTTP/1.1" 200 34
INFO 2020-02-09 17:27:18,004 basehttp 124 "GET /mobiles/17719715757/count/ HTTP/1.1" 200 34
INFO 2020-02-09 17:27:18,119 basehttp 124 "GET /sms_codes/17719715757/?text=rfug&image_code_id=30cf328d-2a48-424a-89b0-d8263ecd0790 HTTP/1.1" 200 16
INFO 2020-02-09 17:27:18,390 tasks 17 发送短信验证码正常[mobile:17719715757]
INFO 2020-02-09 17:27:31,236 basehttp 124 "GET /usernames/jillhero/count/ HTTP/1.1" 200 33
INFO 2020-02-09 17:27:31,238 basehttp 124 "GET /mobiles/17719715757/count/ HTTP/1.1" 200 34
WARNING 2020-02-09 17:27:31,251 basehttp 124 "POST /users/ HTTP/1.1" 400 46
INFO 2020-02-09 17:27:39,650 basehttp 124 "GET /mobiles/17719715757/count/ HTTP/1.1" 200 34
INFO 2020-02-09 17:27:39,653 basehttp 124 "GET /usernames/jillhero/count/ HTTP/1.1" 200 33
WARNING 2020-02-09 17:27:39,659 basehttp 124 "POST /users/ HTTP/1.1" 400 46
INFO 2020-02-09 17:27:47,582 basehttp 124 "GET /image_codes/7a477730-8f31-4446-8395-ea5fdaf4cb13/ HTTP/1.1" 200 3297
INFO 2020-02-09 17:27:50,263 basehttp 124 "GET /usernames/jillhero/count/ HTTP/1.1" 200 33
INFO 2020-02-09 17:27:55,916 basehttp 124 "GET /mobiles/17719715757/count/ HTTP/1.1" 200 34
WARNING 2020-02-09 17:27:59,815 basehttp 124 "GET /sms_codes/17719715757/?text=wszm&image_code_id=7a477730-8f31-4446-8395-ea5fdaf4cb13 HTTP/1.1" 400 49
INFO 2020-02-09 17:27:59,825 basehttp 124 "GET /mobiles/17719715757/count/ HTTP/1.1" 200 34
INFO 2020-02-09 17:27:59,846 basehttp 124 "GET /image_codes/66dcc8e5-3d5b-4ac6-8b4a-a442e940a1b0/ HTTP/1.1" 200 3627
WARNING 2020-02-09 17:28:04,573 basehttp 124 "GET /sms_codes/17719715757/?text=yrhb&image_code_id=66dcc8e5-3d5b-4ac6-8b4a-a442e940a1b0 HTTP/1.1" 400 49
INFO 2020-02-09 17:28:04,586 basehttp 124 "GET /mobiles/17719715757/count/ HTTP/1.1" 200 34
INFO 2020-02-09 17:28:04,606 basehttp 124 "GET /image_codes/a6c878e8-c6e7-4cf3-a169-8bc1398abe44/ HTTP/1.1" 200 3737
WARNING 2020-02-09 17:28:09,170 basehttp 124 "GET /sms_codes/17719715757/?text=rwkd&image_code_id=a6c878e8-c6e7-4cf3-a169-8bc1398abe44 HTTP/1.1" 400 49
INFO 2020-02-09 17:28:09,188 basehttp 124 "GET /mobiles/17719715757/count/ HTTP/1.1" 200 34
INFO 2020-02-09 17:28:09,202 basehttp 124 "GET /image_codes/5d8ea373-9629-488b-aea9-04a4627b65ba/ HTTP/1.1" 200 3264
INFO 2020-02-09 17:28:11,014 basehttp 124 "GET /image_codes/3219aa66-efb2-45ae-ba13-e76844d901ee/ HTTP/1.1" 200 3187
INFO 2020-02-09 17:28:13,535 basehttp 124 "GET /usernames/jillhero/count/ HTTP/1.1" 200 33
INFO 2020-02-09 17:28:18,235 basehttp 124 "GET /mobiles/17719715757/count/ HTTP/1.1" 200 34
INFO 2020-02-09 17:28:20,728 basehttp 124 "GET /sms_codes/17719715757/?text=haqe&image_code_id=3219aa66-efb2-45ae-ba13-e76844d901ee HTTP/1.1" 200 16
INFO 2020-02-09 17:28:20,738 basehttp 124 "GET /mobiles/17719715757/count/ HTTP/1.1" 200 34
INFO 2020-02-09 17:28:20,962 tasks 17 发送短信验证码正常[mobile:17719715757]
INFO 2020-02-09 17:28:34,504 basehttp 124 "GET /mobiles/17719715757/count/ HTTP/1.1" 200 34
WARNING 2020-02-09 17:28:34,510 basehttp 124 "POST /users/ HTTP/1.1" 400 46
INFO 2020-02-09 17:28:34,511 basehttp 124 "GET /usernames/jillhero/count/ HTTP/1.1" 200 33
INFO 2020-02-09 17:31:24,852 basehttp 124 "GET /image_codes/5698ebf1-ff90-459e-b55e-a9b8958f43f8/ HTTP/1.1" 200 2965
INFO 2020-02-09 17:31:27,294 basehttp 124 "GET /usernames/jillhero/count/ HTTP/1.1" 200 33
INFO 2020-02-09 17:31:32,575 basehttp 124 "GET /mobiles/17719715757/count/ HTTP/1.1" 200 34
INFO 2020-02-09 17:31:37,833 basehttp 124 "GET /mobiles/17719715757/count/ HTTP/1.1" 200 34
INFO 2020-02-09 17:31:37,954 basehttp 124 "GET /sms_codes/17719715757/?text=5pcf&image_code_id=5698ebf1-ff90-459e-b55e-a9b8958f43f8 HTTP/1.1" 200 16
INFO 2020-02-09 17:31:38,274 tasks 17 发送短信验证码正常[mobile:17719715757]
INFO 2020-02-09 17:31:48,426 basehttp 124 "GET /mobiles/17719715757/count/ HTTP/1.1" 200 34
INFO 2020-02-09 17:31:48,431 basehttp 124 "GET /usernames/jillhero/count/ HTTP/1.1" 200 33
INFO 2020-02-09 17:31:48,507 basehttp 124 "POST /users/ HTTP/1.1" 201 53
INFO 2020-02-09 19:41:05,295 basehttp 124 "OPTIONS /authorizations/ HTTP/1.1" 200 0
INFO 2020-02-09 19:41:05,371 basehttp 124 "POST /authorizations/ HTTP/1.1" 200 211
INFO 2020-02-09 19:41:13,092 basehttp 124 "OPTIONS /user/ HTTP/1.1" 200 0
WARNING 2020-02-09 19:41:13,108 base 152 Not Found: /user/
WARNING 2020-02-09 19:41:13,109 basehttp 124 "GET /user/ HTTP/1.1" 404 3042
WARNING 2020-02-09 19:41:16,961 base 152 Not Found: /user/
WARNING 2020-02-09 19:41:16,961 basehttp 124 "GET /user/ HTTP/1.1" 404 3042
WARNING 2020-02-09 19:41:19,238 base 152 Not Found: /areas/
WARNING 2020-02-09 19:41:19,240 basehttp 124 "GET /areas/ HTTP/1.1" 404 3045
INFO 2020-02-09 19:41:19,241 basehttp 124 "OPTIONS /addresses/ HTTP/1.1" 200 0
WARNING 2020-02-09 19:41:19,255 base 152 Not Found: /addresses/
WARNING 2020-02-09 19:41:19,256 basehttp 124 "GET /addresses/ HTTP/1.1" 404 3057
WARNING 2020-02-09 19:41:22,877 base 152 Not Found: /user/
WARNING 2020-02-09 19:41:22,878 basehttp 124 "GET /user/ HTTP/1.1" 404 3042
WARNING 2020-02-09 19:41:34,221 base 152 Not Found: /areas/
WARNING 2020-02-09 19:41:34,224 base 152 Not Found: /addresses/
WARNING 2020-02-09 19:41:34,224 basehttp 124 "GET /addresses/ HTTP/1.1" 404 3057
WARNING 2020-02-09 19:41:34,225 basehttp 124 "GET /areas/ HTTP/1.1" 404 3045
INFO 2020-02-10 18:01:27,847 basehttp 124 "GET /oauth/qq/authorization/?next=/ HTTP/1.1" 200 181
WARNING 2020-02-10 20:09:01,334 base 152 Not Found: /
WARNING 2020-02-10 20:09:01,335 basehttp 124 "GET / HTTP/1.1" 404 3110
WARNING 2020-02-10 20:09:01,550 base 152 Not Found: /favicon.ico
WARNING 2020-02-10 20:09:01,551 basehttp 124 "GET /favicon.ico HTTP/1.1" 404 3161
WARNING 2020-02-10 20:09:34,405 base 152 Not Found: /oauth/qq/user/
WARNING 2020-02-10 20:09:34,405 basehttp 124 "GET /oauth/qq/user/?code=E99B117C701676CE5526A8C5BB3208B5 HTTP/1.1" 404 3280
INFO 2020-02-10 20:11:54,970 basehttp 124 "GET /oauth/qq/authorization/?next=/ HTTP/1.1" 200 181
WARNING 2020-02-10 20:17:18,457 base 152 Not Found: /oauth/qq/user/
WARNING 2020-02-10 20:17:18,458 basehttp 124 "GET /oauth/qq/user/?code=839CFCBD53259539F40F6AA630E0EEFC HTTP/1.1" 404 3280
INFO 2020-02-10 20:20:32,325 basehttp 124 "GET /oauth/qq/authorization/?next=/ HTTP/1.1" 200 181
WARNING 2020-02-10 20:20:43,493 base 152 Not Found: /oauth/qq/user/
WARNING 2020-02-10 20:20:43,494 basehttp 124 "GET /oauth/qq/user/?code=3A08EC6C2B9ECE6B7A82A24275D10675 HTTP/1.1" 404 3280
WARNING 2020-02-10 20:23:54,382 base 152 Not Found: /oauth/qq/user/
WARNING 2020-02-10 20:23:54,383 basehttp 124 "GET /oauth/qq/user/?code=9E33ADB6420774BBFCAF9277843FEA71 HTTP/1.1" 404 3280
INFO 2020-02-10 20:24:07,515 basehttp 124 "GET /oauth/qq/authorization/?next=/ HTTP/1.1" 200 181
WARNING 2020-02-10 20:24:15,594 base 152 Not Found: /oauth/qq/user/
WARNING 2020-02-10 20:24:15,594 basehttp 124 "GET /oauth/qq/user/?code=000F3F614AE4CF4336703BFD3D266F5F HTTP/1.1" 404 3280
WARNING 2020-02-10 20:27:31,442 base 152 Not Found: /oauth/qq/user/
WARNING 2020-02-10 20:27:31,443 basehttp 124 "GET /oauth/qq/user/?code=B61E572C055614C5BA24D5641EE93FEA HTTP/1.1" 404 3280
INFO 2020-02-10 20:34:40,936 basehttp 124 "GET /oauth/qq/authorization/?next=/ HTTP/1.1" 200 181
WARNING 2020-02-10 20:34:52,245 base 152 Not Found: /oauth/qq/user/
WARNING 2020-02-10 20:34:52,246 basehttp 124 "GET /oauth/qq/user/?code=B05D5A21D1E66CFFEFABE57182342F99 HTTP/1.1" 404 3280
WARNING 2020-02-10 20:42:18,020 base 152 Not Found: /oauth/qq/user/
WARNING 2020-02-10 20:42:18,021 basehttp 124 "GET /oauth/qq/user/?code=A971575C5831B0CC4A5F6761981A8C2C HTTP/1.1" 404 3280
WARNING 2020-02-10 20:46:42,843 base 152 Not Found: /oauth/qq/user/
WARNING 2020-02-10 20:46:42,844 basehttp 124 "GET /oauth/qq/user/?code=35B87917A351639B1099BF3DC2AD4F78 HTTP/1.1" 404 3280
INFO 2020-02-10 20:48:13,178 basehttp 124 "GET /oauth/qq/authorization/?next=/ HTTP/1.1" 200 181
WARNING 2020-02-10 20:48:21,602 base 152 Not Found: /oauth/qq/user/
WARNING 2020-02-10 20:48:21,602 basehttp 124 "GET /oauth/qq/user/?code=15B2F636C78F1113ED8110AB5AFDAF9C HTTP/1.1" 404 3280
INFO 2020-02-10 20:50:13,351 basehttp 124 "GET /oauth/qq/authorization/?next=/ HTTP/1.1" 200 181
WARNING 2020-02-10 20:50:21,685 base 152 Not Found: /oauth/qq/user/
WARNING 2020-02-10 20:50:21,685 basehttp 124 "GET /oauth/qq/user/?code=3C60F8B730522F878A5F1D7FC68869E8 HTTP/1.1" 404 3280
INFO 2020-02-10 20:59:09,006 basehttp 124 "GET /oauth/qq/authorization/?next=/ HTTP/1.1" 200 195
WARNING 2020-02-10 20:59:20,119 base 152 Not Found: /oauth/qq/user/
WARNING 2020-02-10 20:59:20,119 basehttp 124 "GET /oauth/qq/user/?code=DA42CE0C268A537834B44CD9A483D36A HTTP/1.1" 404 3280
INFO 2020-02-10 21:02:54,248 basehttp 124 "GET /oauth/qq/authorization/?next=/ HTTP/1.1" 200 195
WARNING 2020-02-10 21:03:11,337 base 152 Not Found: /oauth/qq/user/
WARNING 2020-02-10 21:03:11,338 basehttp 124 "GET /oauth/qq/user/?code=90C982BC9C9D8D3320713B04E2817F50 HTTP/1.1" 404 3280
INFO 2020-02-10 21:04:13,700 basehttp 124 "GET /oauth/qq/authorization/?next=/ HTTP/1.1" 200 195
WARNING 2020-02-10 21:04:58,084 base 152 Not Found: /oauth/qq/user/
WARNING 2020-02-10 21:04:58,085 basehttp 124 "GET /oauth/qq/user/?code=7D02D03C769BBEFA01D7E3C023FAC9DD HTTP/1.1" 404 3280
INFO 2020-02-11 14:47:58,302 basehttp 124 "GET /oauth/qq/authorization/?next=/ HTTP/1.1" 200 195
WARNING 2020-02-11 14:49:57,520 base 152 Not Found: /oauth/qq/user/
WARNING 2020-02-11 14:49:57,522 basehttp 124 "GET /oauth/qq/user/?code=D5B0E13278E3E5F9F90CD1538A29287F HTTP/1.1" 404 3280
INFO 2020-02-11 14:51:52,961 basehttp 124 "GET /oauth/qq/authorization/?next=/ HTTP/1.1" 200 195
ERROR 2020-02-11 14:52:19,650 exception 135 Internal Server Error: /oauth/qq/user/
Traceback (most recent call last):
  File "/Users/jill/PycharmProjects/django_mall/mall/mall/apps/oauth/views.py", line 39, in get
    oauth_qq_user = OAuthQQUser.objects.get(openid=openid)
  File "/usr/local/lib/python3.7/site-packages/django/db/models/manager.py", line 85, in manager_method
    return getattr(self.get_queryset(), name)(*args, **kwargs)
  File "/usr/local/lib/python3.7/site-packages/django/db/models/query.py", line 380, in get
    self.model._meta.object_name
oauth.models.DoesNotExist: OAuthQQUser matching query does not exist.

During handling of the above exception, another exception occurred:

Traceback (most recent call last):
  File "/usr/local/lib/python3.7/site-packages/django/core/handlers/exception.py", line 41, in inner
    response = get_response(request)
  File "/usr/local/lib/python3.7/site-packages/django/core/handlers/base.py", line 187, in _get_response
    response = self.process_exception_by_middleware(e, request)
  File "/usr/local/lib/python3.7/site-packages/django/core/handlers/base.py", line 185, in _get_response
    response = wrapped_callback(request, *callback_args, **callback_kwargs)
  File "/usr/local/lib/python3.7/site-packages/django/views/decorators/csrf.py", line 58, in wrapped_view
    return view_func(*args, **kwargs)
  File "/usr/local/lib/python3.7/site-packages/django/views/generic/base.py", line 68, in view
    return self.dispatch(request, *args, **kwargs)
  File "/usr/local/lib/python3.7/site-packages/rest_framework/views.py", line 505, in dispatch
    response = self.handle_exception(exc)
  File "/usr/local/lib/python3.7/site-packages/rest_framework/views.py", line 465, in handle_exception
    self.raise_uncaught_exception(exc)
  File "/usr/local/lib/python3.7/site-packages/rest_framework/views.py", line 476, in raise_uncaught_exception
    raise exc
  File "/usr/local/lib/python3.7/site-packages/rest_framework/views.py", line 502, in dispatch
    response = handler(request, *args, **kwargs)
  File "/Users/jill/PycharmProjects/django_mall/mall/mall/apps/oauth/views.py", line 40, in get
    except OAuthAPIError.DoesNotExist:
AttributeError: type object 'OAuthAPIError' has no attribute 'DoesNotExist'
ERROR 2020-02-11 14:52:19,824 basehttp 124 "GET /oauth/qq/user/?code=BB1485F510D874D03FA93477872DB275 HTTP/1.1" 500 19499
INFO 2020-02-11 14:53:02,971 basehttp 124 "GET /oauth/qq/authorization/?next=/ HTTP/1.1" 200 195
ERROR 2020-02-11 14:53:11,147 exception 135 Internal Server Error: /oauth/qq/user/
Traceback (most recent call last):
  File "/usr/local/lib/python3.7/site-packages/django/core/handlers/exception.py", line 41, in inner
    response = get_response(request)
  File "/usr/local/lib/python3.7/site-packages/django/core/handlers/base.py", line 187, in _get_response
    response = self.process_exception_by_middleware(e, request)
  File "/usr/local/lib/python3.7/site-packages/django/core/handlers/base.py", line 185, in _get_response
    response = wrapped_callback(request, *callback_args, **callback_kwargs)
  File "/usr/local/lib/python3.7/site-packages/django/views/decorators/csrf.py", line 58, in wrapped_view
    return view_func(*args, **kwargs)
  File "/usr/local/lib/python3.7/site-packages/django/views/generic/base.py", line 68, in view
    return self.dispatch(request, *args, **kwargs)
  File "/usr/local/lib/python3.7/site-packages/rest_framework/views.py", line 505, in dispatch
    response = self.handle_exception(exc)
  File "/usr/local/lib/python3.7/site-packages/rest_framework/views.py", line 465, in handle_exception
    self.raise_uncaught_exception(exc)
  File "/usr/local/lib/python3.7/site-packages/rest_framework/views.py", line 476, in raise_uncaught_exception
    raise exc
  File "/usr/local/lib/python3.7/site-packages/rest_framework/views.py", line 502, in dispatch
    response = handler(request, *args, **kwargs)
  File "/Users/jill/PycharmProjects/django_mall/mall/mall/apps/oauth/views.py", line 39, in get
    oauth_qq_user = OAuthQQUser.objects.get(openid=openid)
  File "/usr/local/lib/python3.7/site-packages/django/db/models/manager.py", line 85, in manager_method
    return getattr(self.get_queryset(), name)(*args, **kwargs)
  File "/usr/local/lib/python3.7/site-packages/django/db/models/query.py", line 380, in get
    self.model._meta.object_name
oauth.models.DoesNotExist: OAuthQQUser matching query does not exist.
ERROR 2020-02-11 14:53:11,245 basehttp 124 "GET /oauth/qq/user/?code=B20E19B5DF8B391C6122362336B47BA7 HTTP/1.1" 500 19192
INFO 2020-02-11 14:58:39,247 basehttp 124 "GET /oauth/qq/authorization/?next=/ HTTP/1.1" 200 195
ERROR 2020-02-11 14:59:50,249 exception 135 Internal Server Error: /oauth/qq/user/
Traceback (most recent call last):
  File "/usr/local/lib/python3.7/site-packages/django/core/handlers/exception.py", line 41, in inner
    response = get_response(request)
  File "/usr/local/lib/python3.7/site-packages/django/core/handlers/base.py", line 187, in _get_response
    response = self.process_exception_by_middleware(e, request)
  File "/usr/local/lib/python3.7/site-packages/django/core/handlers/base.py", line 185, in _get_response
    response = wrapped_callback(request, *callback_args, **callback_kwargs)
  File "/usr/local/lib/python3.7/site-packages/django/views/decorators/csrf.py", line 58, in wrapped_view
    return view_func(*args, **kwargs)
  File "/usr/local/lib/python3.7/site-packages/django/views/generic/base.py", line 68, in view
    return self.dispatch(request, *args, **kwargs)
  File "/usr/local/lib/python3.7/site-packages/rest_framework/views.py", line 505, in dispatch
    response = self.handle_exception(exc)
  File "/usr/local/lib/python3.7/site-packages/rest_framework/views.py", line 465, in handle_exception
    self.raise_uncaught_exception(exc)
  File "/usr/local/lib/python3.7/site-packages/rest_framework/views.py", line 476, in raise_uncaught_exception
    raise exc
  File "/usr/local/lib/python3.7/site-packages/rest_framework/views.py", line 502, in dispatch
    response = handler(request, *args, **kwargs)
  File "/Users/jill/PycharmProjects/django_mall/mall/mall/apps/oauth/views.py", line 39, in get
    oauth_qq_user = OAuthQQUser.objects.get(openid=openid)
  File "/usr/local/lib/python3.7/site-packages/django/db/models/manager.py", line 85, in manager_method
    return getattr(self.get_queryset(), name)(*args, **kwargs)
  File "/usr/local/lib/python3.7/site-packages/django/db/models/query.py", line 380, in get
    self.model._meta.object_name
oauth.models.DoesNotExist: OAuthQQUser matching query does not exist.
ERROR 2020-02-11 14:59:50,320 basehttp 124 "GET /oauth/qq/user/?code=F98F99AC4B4472B5A46B53B41D9A2760 HTTP/1.1" 500 19192
INFO 2020-02-11 15:00:59,857 basehttp 124 "GET /oauth/qq/authorization/?next=/ HTTP/1.1" 200 195
INFO 2020-02-11 15:01:04,599 basehttp 124 "GET /oauth/qq/authorization/?next=/ HTTP/1.1" 200 195
ERROR 2020-02-11 15:02:00,512 exception 135 Internal Server Error: /oauth/qq/user/
Traceback (most recent call last):
  File "/Users/jill/PycharmProjects/django_mall/mall/mall/apps/oauth/views.py", line 39, in get
    oauth_qq_user = OAuthQQUser.objects.get(openid=openid)
  File "/usr/local/lib/python3.7/site-packages/django/db/models/manager.py", line 85, in manager_method
    return getattr(self.get_queryset(), name)(*args, **kwargs)
  File "/usr/local/lib/python3.7/site-packages/django/db/models/query.py", line 380, in get
    self.model._meta.object_name
oauth.models.DoesNotExist: OAuthQQUser matching query does not exist.

During handling of the above exception, another exception occurred:

Traceback (most recent call last):
  File "/usr/local/lib/python3.7/site-packages/django/core/handlers/exception.py", line 41, in inner
    response = get_response(request)
  File "/usr/local/lib/python3.7/site-packages/django/core/handlers/base.py", line 187, in _get_response
    response = self.process_exception_by_middleware(e, request)
  File "/usr/local/lib/python3.7/site-packages/django/core/handlers/base.py", line 185, in _get_response
    response = wrapped_callback(request, *callback_args, **callback_kwargs)
  File "/usr/local/lib/python3.7/site-packages/django/views/decorators/csrf.py", line 58, in wrapped_view
    return view_func(*args, **kwargs)
  File "/usr/local/lib/python3.7/site-packages/django/views/generic/base.py", line 68, in view
    return self.dispatch(request, *args, **kwargs)
  File "/usr/local/lib/python3.7/site-packages/rest_framework/views.py", line 505, in dispatch
    response = self.handle_exception(exc)
  File "/usr/local/lib/python3.7/site-packages/rest_framework/views.py", line 465, in handle_exception
    self.raise_uncaught_exception(exc)
  File "/usr/local/lib/python3.7/site-packages/rest_framework/views.py", line 476, in raise_uncaught_exception
    raise exc
  File "/usr/local/lib/python3.7/site-packages/rest_framework/views.py", line 502, in dispatch
    response = handler(request, *args, **kwargs)
  File "/Users/jill/PycharmProjects/django_mall/mall/mall/apps/oauth/views.py", line 40, in get
    except OAuthAPIError.DoesNotExist:
AttributeError: type object 'OAuthAPIError' has no attribute 'DoesNotExist'
ERROR 2020-02-11 15:02:01,205 basehttp 124 "GET /oauth/qq/user/?code=98FF560857552CF8D442EFAC9ACC6591 HTTP/1.1" 500 19499
INFO 2020-02-11 15:04:39,793 basehttp 124 "GET /oauth/qq/authorization/?next=/ HTTP/1.1" 200 181
INFO 2020-02-11 15:05:02,330 basehttp 124 "GET /oauth/qq/authorization/?next=/ HTTP/1.1" 200 181
ERROR 2020-02-11 15:05:21,953 exception 135 Internal Server Error: /oauth/qq/user/
Traceback (most recent call last):
  File "/Users/jill/PycharmProjects/django_mall/mall/mall/apps/oauth/views.py", line 39, in get
    oauth_qq_user = OAuthQQUser.objects.get(openid=openid)
  File "/usr/local/lib/python3.7/site-packages/django/db/models/manager.py", line 85, in manager_method
    return getattr(self.get_queryset(), name)(*args, **kwargs)
  File "/usr/local/lib/python3.7/site-packages/django/db/models/query.py", line 380, in get
    self.model._meta.object_name
oauth.models.DoesNotExist: OAuthQQUser matching query does not exist.

During handling of the above exception, another exception occurred:

Traceback (most recent call last):
  File "/usr/local/lib/python3.7/site-packages/django/core/handlers/exception.py", line 41, in inner
    response = get_response(request)
  File "/usr/local/lib/python3.7/site-packages/django/core/handlers/base.py", line 187, in _get_response
    response = self.process_exception_by_middleware(e, request)
  File "/usr/local/lib/python3.7/site-packages/django/core/handlers/base.py", line 185, in _get_response
    response = wrapped_callback(request, *callback_args, **callback_kwargs)
  File "/usr/local/lib/python3.7/site-packages/django/views/decorators/csrf.py", line 58, in wrapped_view
    return view_func(*args, **kwargs)
  File "/usr/local/lib/python3.7/site-packages/django/views/generic/base.py", line 68, in view
    return self.dispatch(request, *args, **kwargs)
  File "/usr/local/lib/python3.7/site-packages/rest_framework/views.py", line 505, in dispatch
    response = self.handle_exception(exc)
  File "/usr/local/lib/python3.7/site-packages/rest_framework/views.py", line 465, in handle_exception
    self.raise_uncaught_exception(exc)
  File "/usr/local/lib/python3.7/site-packages/rest_framework/views.py", line 476, in raise_uncaught_exception
    raise exc
  File "/usr/local/lib/python3.7/site-packages/rest_framework/views.py", line 502, in dispatch
    response = handler(request, *args, **kwargs)
  File "/Users/jill/PycharmProjects/django_mall/mall/mall/apps/oauth/views.py", line 40, in get
    except OAuthAPIError.DoesNotExist:
AttributeError: type object 'OAuthAPIError' has no attribute 'DoesNotExist'
ERROR 2020-02-11 15:05:22,091 basehttp 124 "GET /oauth/qq/user/?code=02D414DC60BF056637EB21D31CB5200D HTTP/1.1" 500 19505
INFO 2020-02-11 15:08:53,887 basehttp 124 "GET /oauth/qq/authorization/?next=/ HTTP/1.1" 200 181
INFO 2020-02-11 15:09:11,311 basehttp 124 "GET /oauth/qq/user/?code=DED0233A959CA3D218306039097E1DC5 HTTP/1.1" 200 233
INFO 2020-02-11 15:09:11,381 basehttp 124 "GET /image_codes/445a0dbd-51b3-4f39-a2b8-ec43b0fb498d/ HTTP/1.1" 200 3487
WARNING 2020-02-11 17:45:50,728 base 152 Not Found: /
WARNING 2020-02-11 17:45:50,729 basehttp 124 "GET / HTTP/1.1" 404 3110
WARNING 2020-02-11 17:45:51,085 base 152 Not Found: /favicon.ico
WARNING 2020-02-11 17:45:51,085 basehttp 124 "GET /favicon.ico HTTP/1.1" 404 3161
ERROR 2020-02-11 17:46:00,468 exception 135 Internal Server Error: /oauth/qq/user/
Traceback (most recent call last):
  File "/usr/local/lib/python3.7/site-packages/django/core/handlers/exception.py", line 41, in inner
    response = get_response(request)
  File "/usr/local/lib/python3.7/site-packages/django/core/handlers/base.py", line 187, in _get_response
    response = self.process_exception_by_middleware(e, request)
  File "/usr/local/lib/python3.7/site-packages/django/core/handlers/base.py", line 185, in _get_response
    response = wrapped_callback(request, *callback_args, **callback_kwargs)
  File "/usr/local/lib/python3.7/site-packages/django/views/decorators/csrf.py", line 58, in wrapped_view
    return view_func(*args, **kwargs)
  File "/usr/local/lib/python3.7/site-packages/django/views/generic/base.py", line 68, in view
    return self.dispatch(request, *args, **kwargs)
  File "/usr/local/lib/python3.7/site-packages/rest_framework/views.py", line 505, in dispatch
    response = self.handle_exception(exc)
  File "/usr/local/lib/python3.7/site-packages/rest_framework/views.py", line 465, in handle_exception
    self.raise_uncaught_exception(exc)
  File "/usr/local/lib/python3.7/site-packages/rest_framework/views.py", line 476, in raise_uncaught_exception
    raise exc
  File "/usr/local/lib/python3.7/site-packages/rest_framework/views.py", line 502, in dispatch
    response = handler(request, *args, **kwargs)
  File "/Users/jill/PycharmProjects/django_mall/mall/mall/apps/oauth/views.py", line 35, in get
    access_token = oauth_qq.get_access_token(code)
  File "/Users/jill/PycharmProjects/django_mall/mall/mall/apps/oauth/utils.py", line 60, in get_access_token
    return access_token[0]
TypeError: 'NoneType' object is not subscriptable
ERROR 2020-02-11 17:46:00,536 basehttp 124 "GET /oauth/qq/user/?code=DED0233A959CA3D218306039097E1DC5 HTTP/1.1" 500 17562
INFO 2020-02-11 17:46:14,304 basehttp 124 "GET /oauth/qq/authorization/?next=/ HTTP/1.1" 200 181
ERROR 2020-02-11 17:47:37,246 utils 72 获取openid异常[Errno 60] Operation timed out
ERROR 2020-02-11 17:47:37,255 basehttp 124 "GET /oauth/qq/user/?code=85348DB684097149F4044AE50FDF7B53 HTTP/1.1" 503 34
INFO 2020-02-11 17:49:27,614 basehttp 124 "GET /oauth/qq/authorization/?next=/ HTTP/1.1" 200 181
INFO 2020-02-11 17:49:39,685 basehttp 124 "GET /oauth/qq/user/?code=25D68C16C4D04DEEE727F89C96712664 HTTP/1.1" 200 233
INFO 2020-02-11 17:49:39,716 basehttp 124 "GET /image_codes/cba0aa4b-335d-48ed-8f53-c54885074751/ HTTP/1.1" 200 3492
INFO 2020-02-11 17:49:49,859 basehttp 124 "GET /sms_codes/17719715757/?text=wgfq&image_code_id=cba0aa4b-335d-48ed-8f53-c54885074751 HTTP/1.1" 200 16
INFO 2020-02-11 17:51:36,841 basehttp 124 "GET /sms_codes/17719715757/?text=wgfq&image_code_id=cba0aa4b-335d-48ed-8f53-c54885074751 HTTP/1.1" 200 16
INFO 2020-02-11 17:52:26,906 basehttp 124 "OPTIONS /oauth/qq/user/ HTTP/1.1" 200 0
WARNING 2020-02-11 17:52:26,916 basehttp 124 "POST /oauth/qq/user/ HTTP/1.1" 400 88
WARNING 2020-02-11 17:52:32,510 basehttp 124 "POST /oauth/qq/user/ HTTP/1.1" 400 88
WARNING 2020-02-11 17:52:48,237 basehttp 124 "GET /oauth/qq/user/ HTTP/1.1" 400 14175
INFO 2020-02-11 17:52:48,559 basehttp 124 "GET /static/rest_framework/css/bootstrap-tweaks.css HTTP/1.1" 200 3385
INFO 2020-02-11 17:52:48,560 basehttp 124 "GET /static/rest_framework/css/prettify.css HTTP/1.1" 200 817
INFO 2020-02-11 17:52:48,561 basehttp 124 "GET /static/rest_framework/css/bootstrap.min.css HTTP/1.1" 200 121457
INFO 2020-02-11 17:52:48,570 basehttp 124 "GET /static/rest_framework/css/default.css HTTP/1.1" 200 1131
INFO 2020-02-11 17:52:48,583 basehttp 124 "GET /static/rest_framework/js/prettify-min.js HTTP/1.1" 200 13632
INFO 2020-02-11 17:52:48,584 basehttp 124 "GET /static/rest_framework/js/csrf.js HTTP/1.1" 200 1719
INFO 2020-02-11 17:52:48,586 basehttp 124 "GET /static/rest_framework/js/default.js HTTP/1.1" 200 1268
INFO 2020-02-11 17:52:48,587 basehttp 124 "GET /static/rest_framework/js/ajax-form.js HTTP/1.1" 200 3597
INFO 2020-02-11 17:52:48,588 basehttp 124 "GET /static/rest_framework/js/jquery-3.4.1.min.js HTTP/1.1" 200 88145
INFO 2020-02-11 17:52:48,590 basehttp 124 "GET /static/rest_framework/js/bootstrap.min.js HTTP/1.1" 200 39680
INFO 2020-02-11 17:52:48,619 basehttp 124 "GET /static/rest_framework/img/grid.png HTTP/1.1" 200 1458
WARNING 2020-02-11 17:52:49,122 base 152 Not Found: /favicon.ico
WARNING 2020-02-11 17:52:49,123 basehttp 124 "GET /favicon.ico HTTP/1.1" 404 3167
ERROR 2020-02-11 17:57:40,261 exception 135 Internal Server Error: /oauth/qq/user/
Traceback (most recent call last):
  File "/usr/local/lib/python3.7/site-packages/django/core/handlers/exception.py", line 41, in inner
    response = get_response(request)
  File "/usr/local/lib/python3.7/site-packages/django/core/handlers/base.py", line 187, in _get_response
    response = self.process_exception_by_middleware(e, request)
  File "/usr/local/lib/python3.7/site-packages/django/core/handlers/base.py", line 185, in _get_response
    response = wrapped_callback(request, *callback_args, **callback_kwargs)
  File "/usr/local/lib/python3.7/site-packages/django/views/decorators/csrf.py", line 58, in wrapped_view
    return view_func(*args, **kwargs)
  File "/usr/local/lib/python3.7/site-packages/django/views/generic/base.py", line 68, in view
    return self.dispatch(request, *args, **kwargs)
  File "/usr/local/lib/python3.7/site-packages/rest_framework/views.py", line 505, in dispatch
    response = self.handle_exception(exc)
  File "/usr/local/lib/python3.7/site-packages/rest_framework/views.py", line 465, in handle_exception
    self.raise_uncaught_exception(exc)
  File "/usr/local/lib/python3.7/site-packages/rest_framework/views.py", line 476, in raise_uncaught_exception
    raise exc
  File "/usr/local/lib/python3.7/site-packages/rest_framework/views.py", line 502, in dispatch
    response = handler(request, *args, **kwargs)
  File "/Users/jill/PycharmProjects/django_mall/mall/mall/apps/oauth/views.py", line 35, in get
    access_token = oauth_qq.get_access_token(code)
  File "/Users/jill/PycharmProjects/django_mall/mall/mall/apps/oauth/utils.py", line 61, in get_access_token
    return access_token[0]
TypeError: 'NoneType' object is not subscriptable
ERROR 2020-02-11 17:57:40,387 basehttp 124 "GET /oauth/qq/user/?code=25D68C16C4D04DEEE727F89C96712664 HTTP/1.1" 500 19009
INFO 2020-02-11 17:58:18,254 basehttp 124 "GET /oauth/qq/user/?code=D3BD82A3BB232AA42847C9615363C3DE HTTP/1.1" 200 233
INFO 2020-02-11 17:58:18,344 basehttp 124 "GET /image_codes/ced8c84a-6f93-43da-85c2-3f5180f4ab00/ HTTP/1.1" 200 3014
INFO 2020-02-11 17:58:29,787 basehttp 124 "GET /sms_codes/17719715757/?text=fmwj&image_code_id=ced8c84a-6f93-43da-85c2-3f5180f4ab00 HTTP/1.1" 200 16
WARNING 2020-02-11 17:58:40,176 basehttp 124 "POST /oauth/qq/user/ HTTP/1.1" 400 88
INFO 2020-02-11 18:04:25,001 basehttp 124 "GET /oauth/qq/authorization/?next=/ HTTP/1.1" 200 181
INFO 2020-02-11 18:04:34,196 basehttp 124 "GET /oauth/qq/user/?code=4F574A56EFB933823484DE496B17D458 HTTP/1.1" 200 233
INFO 2020-02-11 18:04:34,229 basehttp 124 "GET /image_codes/7be4ff9e-30c6-4019-80d3-e961fcf129dc/ HTTP/1.1" 200 3201
INFO 2020-02-11 18:04:42,808 basehttp 124 "GET /sms_codes/17719715757/?text=oiq9&image_code_id=7be4ff9e-30c6-4019-80d3-e961fcf129dc HTTP/1.1" 200 16
WARNING 2020-02-11 18:04:51,317 basehttp 124 "POST /oauth/qq/user/ HTTP/1.1" 400 41
INFO 2020-02-11 18:06:03,080 basehttp 124 "GET /oauth/qq/user/?code=F24CB9C3A7891C0328772E8113B6B6E2 HTTP/1.1" 200 233
INFO 2020-02-11 18:06:03,110 basehttp 124 "GET /image_codes/d04d30ae-db5f-4669-91da-f0736021a641/ HTTP/1.1" 200 3111
WARNING 2020-02-11 18:06:12,309 basehttp 124 "GET /sms_codes/17719715757/?text=liqb&image_code_id=d04d30ae-db5f-4669-91da-f0736021a641 HTTP/1.1" 400 46
INFO 2020-02-11 18:06:13,825 basehttp 124 "GET /image_codes/e67f8795-e27a-48cb-a369-f667d69d76c5/ HTTP/1.1" 200 3426
INFO 2020-02-11 18:06:17,430 basehttp 124 "GET /sms_codes/17719715757/?text=orrw&image_code_id=e67f8795-e27a-48cb-a369-f667d69d76c5 HTTP/1.1" 200 16
WARNING 2020-02-11 18:06:25,527 basehttp 124 "POST /oauth/qq/user/ HTTP/1.1" 400 46
ERROR 2020-02-11 18:06:37,221 exception 135 Internal Server Error: /oauth/qq/user/
Traceback (most recent call last):
  File "/usr/local/lib/python3.7/site-packages/django/core/handlers/exception.py", line 41, in inner
    response = get_response(request)
  File "/usr/local/lib/python3.7/site-packages/django/core/handlers/base.py", line 187, in _get_response
    response = self.process_exception_by_middleware(e, request)
  File "/usr/local/lib/python3.7/site-packages/django/core/handlers/base.py", line 185, in _get_response
    response = wrapped_callback(request, *callback_args, **callback_kwargs)
  File "/usr/local/lib/python3.7/site-packages/django/views/decorators/csrf.py", line 58, in wrapped_view
    return view_func(*args, **kwargs)
  File "/usr/local/lib/python3.7/site-packages/django/views/generic/base.py", line 68, in view
    return self.dispatch(request, *args, **kwargs)
  File "/usr/local/lib/python3.7/site-packages/rest_framework/views.py", line 505, in dispatch
    response = self.handle_exception(exc)
  File "/usr/local/lib/python3.7/site-packages/rest_framework/views.py", line 465, in handle_exception
    self.raise_uncaught_exception(exc)
  File "/usr/local/lib/python3.7/site-packages/rest_framework/views.py", line 476, in raise_uncaught_exception
    raise exc
  File "/usr/local/lib/python3.7/site-packages/rest_framework/views.py", line 502, in dispatch
    response = handler(request, *args, **kwargs)
  File "/Users/jill/PycharmProjects/django_mall/mall/mall/apps/oauth/views.py", line 35, in get
    access_token = oauth_qq.get_access_token(code)
  File "/Users/jill/PycharmProjects/django_mall/mall/mall/apps/oauth/utils.py", line 61, in get_access_token
    return access_token[0]
TypeError: 'NoneType' object is not subscriptable
ERROR 2020-02-11 18:06:37,290 basehttp 124 "GET /oauth/qq/user/?code=F24CB9C3A7891C0328772E8113B6B6E2 HTTP/1.1" 500 17562
INFO 2020-02-11 18:06:40,976 basehttp 124 "GET /oauth/qq/authorization/?next=/ HTTP/1.1" 200 181
INFO 2020-02-11 18:06:50,035 basehttp 124 "GET /oauth/qq/user/?code=5D6488B10971BA1E2DD45E248F51A724 HTTP/1.1" 200 233
INFO 2020-02-11 18:06:50,071 basehttp 124 "GET /image_codes/fb8a18f1-5635-4c14-aeb5-2bbf3fa92412/ HTTP/1.1" 200 2963
WARNING 2020-02-11 18:07:01,793 basehttp 124 "GET /sms_codes/17719715757/?text=ucic&image_code_id=fb8a18f1-5635-4c14-aeb5-2bbf3fa92412 HTTP/1.1" 400 49
INFO 2020-02-11 18:07:04,713 basehttp 124 "GET /image_codes/c4937d50-6ef1-4df2-a430-8718cf1676c2/ HTTP/1.1" 200 3434
WARNING 2020-02-11 18:07:09,456 basehttp 124 "GET /sms_codes/17719715757/?text=o5te&image_code_id=c4937d50-6ef1-4df2-a430-8718cf1676c2 HTTP/1.1" 400 49
WARNING 2020-02-11 18:07:10,521 basehttp 124 "GET /sms_codes/17719715757/?text=o5te&image_code_id=c4937d50-6ef1-4df2-a430-8718cf1676c2 HTTP/1.1" 400 49
INFO 2020-02-11 18:07:11,117 basehttp 124 "GET /image_codes/f11a8ed6-c35f-4180-bf3c-ef4b916febb3/ HTTP/1.1" 200 3352
WARNING 2020-02-11 18:07:14,529 basehttp 124 "GET /sms_codes/17719715757/?text=orgz&image_code_id=f11a8ed6-c35f-4180-bf3c-ef4b916febb3 HTTP/1.1" 400 49
WARNING 2020-02-11 18:07:15,138 basehttp 124 "GET /sms_codes/17719715757/?text=orgz&image_code_id=f11a8ed6-c35f-4180-bf3c-ef4b916febb3 HTTP/1.1" 400 49
WARNING 2020-02-11 18:07:15,315 basehttp 124 "GET /sms_codes/17719715757/?text=orgz&image_code_id=f11a8ed6-c35f-4180-bf3c-ef4b916febb3 HTTP/1.1" 400 49
ERROR 2020-02-11 18:07:16,622 exception 135 Internal Server Error: /oauth/qq/user/
Traceback (most recent call last):
  File "/usr/local/lib/python3.7/site-packages/django/core/handlers/exception.py", line 41, in inner
    response = get_response(request)
  File "/usr/local/lib/python3.7/site-packages/django/core/handlers/base.py", line 187, in _get_response
    response = self.process_exception_by_middleware(e, request)
  File "/usr/local/lib/python3.7/site-packages/django/core/handlers/base.py", line 185, in _get_response
    response = wrapped_callback(request, *callback_args, **callback_kwargs)
  File "/usr/local/lib/python3.7/site-packages/django/views/decorators/csrf.py", line 58, in wrapped_view
    return view_func(*args, **kwargs)
  File "/usr/local/lib/python3.7/site-packages/django/views/generic/base.py", line 68, in view
    return self.dispatch(request, *args, **kwargs)
  File "/usr/local/lib/python3.7/site-packages/rest_framework/views.py", line 505, in dispatch
    response = self.handle_exception(exc)
  File "/usr/local/lib/python3.7/site-packages/rest_framework/views.py", line 465, in handle_exception
    self.raise_uncaught_exception(exc)
  File "/usr/local/lib/python3.7/site-packages/rest_framework/views.py", line 476, in raise_uncaught_exception
    raise exc
  File "/usr/local/lib/python3.7/site-packages/rest_framework/views.py", line 502, in dispatch
    response = handler(request, *args, **kwargs)
  File "/Users/jill/PycharmProjects/django_mall/mall/mall/apps/oauth/views.py", line 35, in get
    access_token = oauth_qq.get_access_token(code)
  File "/Users/jill/PycharmProjects/django_mall/mall/mall/apps/oauth/utils.py", line 61, in get_access_token
    return access_token[0]
TypeError: 'NoneType' object is not subscriptable
ERROR 2020-02-11 18:07:16,640 basehttp 124 "GET /oauth/qq/user/?code=5D6488B10971BA1E2DD45E248F51A724 HTTP/1.1" 500 17562
INFO 2020-02-11 18:07:29,963 basehttp 124 "GET /oauth/qq/user/?code=24BA279D855D51EC4504660B0557E6B4 HTTP/1.1" 200 233
INFO 2020-02-11 18:07:29,994 basehttp 124 "GET /image_codes/6f6bb969-2d0e-41a6-bd09-b51541a309d7/ HTTP/1.1" 200 3276
INFO 2020-02-11 18:07:37,558 basehttp 124 "GET /sms_codes/17719715757/?text=sh3a&image_code_id=6f6bb969-2d0e-41a6-bd09-b51541a309d7 HTTP/1.1" 200 16
WARNING 2020-02-11 18:07:45,986 basehttp 124 "POST /oauth/qq/user/ HTTP/1.1" 400 46
ERROR 2020-02-11 18:08:42,721 exception 135 Internal Server Error: /oauth/qq/user/
Traceback (most recent call last):
  File "/usr/local/lib/python3.7/site-packages/django/core/handlers/exception.py", line 41, in inner
    response = get_response(request)
  File "/usr/local/lib/python3.7/site-packages/django/core/handlers/base.py", line 187, in _get_response
    response = self.process_exception_by_middleware(e, request)
  File "/usr/local/lib/python3.7/site-packages/django/core/handlers/base.py", line 185, in _get_response
    response = wrapped_callback(request, *callback_args, **callback_kwargs)
  File "/usr/local/lib/python3.7/site-packages/django/views/decorators/csrf.py", line 58, in wrapped_view
    return view_func(*args, **kwargs)
  File "/usr/local/lib/python3.7/site-packages/django/views/generic/base.py", line 68, in view
    return self.dispatch(request, *args, **kwargs)
  File "/usr/local/lib/python3.7/site-packages/rest_framework/views.py", line 505, in dispatch
    response = self.handle_exception(exc)
  File "/usr/local/lib/python3.7/site-packages/rest_framework/views.py", line 465, in handle_exception
    self.raise_uncaught_exception(exc)
  File "/usr/local/lib/python3.7/site-packages/rest_framework/views.py", line 476, in raise_uncaught_exception
    raise exc
  File "/usr/local/lib/python3.7/site-packages/rest_framework/views.py", line 502, in dispatch
    response = handler(request, *args, **kwargs)
  File "/Users/jill/PycharmProjects/django_mall/mall/mall/apps/oauth/views.py", line 35, in get
    access_token = oauth_qq.get_access_token(code)
  File "/Users/jill/PycharmProjects/django_mall/mall/mall/apps/oauth/utils.py", line 61, in get_access_token
    return access_token[0]
TypeError: 'NoneType' object is not subscriptable
ERROR 2020-02-11 18:08:42,787 basehttp 124 "GET /oauth/qq/user/?code=24BA279D855D51EC4504660B0557E6B4 HTTP/1.1" 500 17562
INFO 2020-02-11 18:08:54,172 basehttp 124 "GET /oauth/qq/user/?code=5FA94C827D282960072CBFB7C1E5D8B1 HTTP/1.1" 200 233
INFO 2020-02-11 18:08:54,202 basehttp 124 "GET /image_codes/02f34cf4-d0c5-4734-9f47-c579ec1f1cf0/ HTTP/1.1" 200 3007
INFO 2020-02-11 18:09:01,829 basehttp 124 "GET /sms_codes/17719715757/?text=9y4e&image_code_id=02f34cf4-d0c5-4734-9f47-c579ec1f1cf0 HTTP/1.1" 200 16
WARNING 2020-02-11 18:09:09,601 basehttp 124 "POST /oauth/qq/user/ HTTP/1.1" 400 46
WARNING 2020-02-11 18:09:22,604 basehttp 124 "POST /oauth/qq/user/ HTTP/1.1" 400 46
WARNING 2020-02-11 18:09:23,548 basehttp 124 "POST /oauth/qq/user/ HTTP/1.1" 400 46
INFO 2020-02-11 18:10:16,194 basehttp 124 "GET /oauth/qq/authorization/?next=/ HTTP/1.1" 200 181
INFO 2020-02-11 18:10:24,854 basehttp 124 "GET /oauth/qq/user/?code=3BC255E8F4B2E5577BB47D5F60F2617C HTTP/1.1" 200 233
INFO 2020-02-11 18:10:24,882 basehttp 124 "GET /image_codes/20994f2f-4fb6-4143-a87c-a38a9babd442/ HTTP/1.1" 200 3178
INFO 2020-02-11 18:10:34,997 basehttp 124 "GET /image_codes/c555bb51-cb22-4802-b51d-0b3833b1355b/ HTTP/1.1" 200 2887
INFO 2020-02-11 18:10:38,799 basehttp 124 "GET /sms_codes/17719715757/?text=kjti&image_code_id=c555bb51-cb22-4802-b51d-0b3833b1355b HTTP/1.1" 200 16
WARNING 2020-02-11 18:10:48,203 basehttp 124 "POST /oauth/qq/user/ HTTP/1.1" 400 46
INFO 2020-02-11 18:12:01,375 basehttp 124 "GET /oauth/qq/user/?code=89E2B21148FA935BA112ED7459418596 HTTP/1.1" 200 233
INFO 2020-02-11 18:12:01,407 basehttp 124 "GET /image_codes/5ae54aab-570e-4c91-b424-326fc43b02a3/ HTTP/1.1" 200 3764
INFO 2020-02-11 18:12:09,383 basehttp 124 "GET /image_codes/0a6aab87-db93-4928-8f68-75d0acad3494/ HTTP/1.1" 200 3157
INFO 2020-02-11 18:12:10,521 basehttp 124 "GET /image_codes/d57b76ab-d0a9-49dc-ac9e-1ddf8856b0ea/ HTTP/1.1" 200 3067
INFO 2020-02-11 18:12:14,166 basehttp 124 "GET /sms_codes/17719715757/?text=8xnu&image_code_id=d57b76ab-d0a9-49dc-ac9e-1ddf8856b0ea HTTP/1.1" 200 16
INFO 2020-02-11 18:12:20,548 basehttp 124 "POST /oauth/qq/user/ HTTP/1.1" 201 229
INFO 2020-02-11 18:16:14,760 basehttp 124 "GET /image_codes/f25bb32e-63a7-4915-911d-06b20fbfe531/ HTTP/1.1" 200 3089
INFO 2020-02-11 18:16:36,134 basehttp 124 "GET /oauth/qq/user/?code=9B39568EF142DB0B2B77352DA785A364 HTTP/1.1" 200 211
INFO 2020-02-11 18:19:01,588 basehttp 124 "OPTIONS /authorizations/ HTTP/1.1" 200 0
INFO 2020-02-11 18:19:01,666 basehttp 124 "POST /authorizations/ HTTP/1.1" 200 211
INFO 2020-02-11 18:19:01,921 basehttp 124 "OPTIONS /user/ HTTP/1.1" 200 0
WARNING 2020-02-11 18:19:01,933 base 152 Not Found: /user/
WARNING 2020-02-11 18:19:01,935 basehttp 124 "GET /user/ HTTP/1.1" 404 3149
WARNING 2020-02-11 18:19:06,394 base 152 Not Found: /areas/
WARNING 2020-02-11 18:19:06,395 basehttp 124 "GET /areas/ HTTP/1.1" 404 3152
INFO 2020-02-11 18:19:06,398 basehttp 124 "OPTIONS /addresses/ HTTP/1.1" 200 0
WARNING 2020-02-11 18:19:06,464 base 152 Not Found: /addresses/
WARNING 2020-02-11 18:19:06,464 basehttp 124 "GET /addresses/ HTTP/1.1" 404 3164
